Workbook

Sheet README
A1: TransferIQ synthetic data set (v2: Northeastern + NYU)
A2: Purpose | B2: Test data for the EvoHack 2026 transfer credit evaluation prototype (Boston University problem statement).
A3: Status | B3: TEST DATA. Students, grades, transcripts, syllabus content, instructors and decisions are invented. Transcripts and syllabi were NOT issued by Northeastern or NYU.
A4: Source schools | B4: Northeastern University (NEU) and New York University (NYU), as given in the hackathon workbook. Two fictional helper schools cover cases NU/NYU cannot: Pinecrest State College (quarter calendar, 1 course) and Summit Online Institute (not regionally accredited, 2 courses).
A5: BU courses | B5: 150 courses across 5 majors. 41 codes/titles come from the provided BU workbook; 109 are synthetic. All descriptions, topics and outcomes are synthetic.
A6: External courses | B6: 194 courses: 76 real NU/NYU catalog courses (code, title, credits from the workbook; content synthetic) + 115 synthetic NU/NYU-style courses + 3 helper-school courses. See the Source column.
A7: Ground truth | B7: Columns with a dark red header (gt_*) are answer keys. For the 76 real courses the counterpart follows the workbook's Course Match sheet. Hide gt_* from the AI matcher.
A8: Past decisions | B8: 100 decisions = the stand-in equivalency table. split = train (reusable, 70) or holdout (hidden from the app, used to measure AI accuracy, 30).
A9: Transcripts | B9: 4 students, 7 transcript PDFs, 56 course lines. Transcript Lines shows the expected rules-engine outcome for each line.
A10: Syllabi | B10: 12 syllabus PDFs: demo maybe-courses, one incomplete (TM), one with a prompt-injection line (red team), three for held-out courses.
A11: Codes (assumption) | B11: Elective codes follow the sponsor's 'ends in TR' rule: CAS <DEPT> 1TR (100-level) / 2TR (200+), TFRGEN 1TR for general electives. No credit = TFRGEN NOCRDT, 0 units, TX.
A12: Formulas | B12: Transcript Lines 'Units if approved' and the Students summary columns are live formulas.
A13: Seed files | B13: seed/*.csv (one per sheet; list fields joined with ' | ') and seed/transferiq_seed.json (lists kept as arrays).

Sheet Demo Scenario
A1: Step | B1: Stage | C1: Action / input | D1: Expected result
A2: 1 | B2: Upload | C2: Maya uploads Transcript_SYN-24001_NYU and Transcript_SYN-24001_PSC | D2: 6 lines extracted; PSY 215 flagged quarter-system
A3: 2 | B3: Instant matches | C3: NYU PSYCH-UA 1, MATH-UA 121, ECON-UA 2 hit the equivalency table | D3: CAS PS 101, CAS MA 123, CAS EC 101; 4 units each; grade T
A4: 3 | B4: Quarter course | C4: PSC PSY 215 Psychology of Music, 4 qtr credits, B | D4: Elective CAS PS 2TR, 2.67 units
A5: 4 | B5: Maybe 1 | C5: NYU PSYCH-UA 10 with Syllabus_NYU_PSYCH-UA-10.pdf on file | D5: AI: ~75% overlap with CAS PS 211 -> evaluator decides (workbook: partial, statistics vs experimental design)
A6: 5 | B6: Maybe 2 | C6: NYU PSYCH-UA 25 Cognitive Neuroscience, no syllabus | D6: TS status; preliminary suggestion from description; reminders day 7/21/45
A7: 6 | B7: Evaluator | C7: Open PSYCH-UA 10; comparison already done; approve with reason code | D7: Decision saved, reusable = Yes
A8: 7 | B8: Late upload | C8: Maya uploads Syllabus_NYU_PSYCH-UA-25.pdf | D8: AI: ~62% overlap with CAS PS 231 -> evaluator decides (expected: elective CAS PS 2TR)
A9: 8 | B9: Posting | C9: Department -> Registrar -> MyBU-style CSV | D9: Secured credit updates; Liam's NYU PSYCH-UA 10 now matches instantly

Sheet Students
A1: Student ID | B1: Name | C1: Intended BU major | D1: BU school | E1: BU start term | F1: Story | G1: Transcript lines | H1: Units secured (matched) | I1: Units pending (maybe/review) | J1: No-credit lines | K1: Email | L1: Phone | M1: Address | N1: Previous school
A2: SYN-24001 | B2: Maya R. Delgado | C2: Psychology | D2: College of Arts & Sciences | E2: Fall 2026 | F2: Demo student from NYU: 6 courses (3 existing matches, 2 maybe, 1 summer quarter-system course) | G2: =COUNTIF('Transcript Lines'!$B$2:$B$57,A2) | H2: =SUMIFS('Transcript Lines'!$M$2:$M$57,'Transcript Lines'!$B$2:$B$57,A2,'Transcript Lines'!$K$2:$K$57,"Matched*") | I2: =SUMIFS('Transcript Lines'!$J$2:$J$57,'Transcript Lines'!$B$2:$B$57,A2,'Transcript Lines'!$K$2:$K$57,"Maybe*")+SUMIFS('Transcript Lines'!$J$2:$J$57,'Transcript Lines'!$B$2:$B$57,A2,'Transcript Lines'!$K$2:$K$57,"Pending*") | J2: =COUNTIFS('Transcript Lines'!$B$2:$B$57,A2,'Transcript Lines'!$N$2:$N$57,"TX") | K2: maya.delgado@example.edu | L2: 212-555-0141 | M2: 418 Quillfeather Row, Apt 3B, Brooklyn, NY 11215 | N2: NYU
A3: SYN-24002 | B3: Jordan A. Reyes | C3: Computer Science | D3: College of Arts & Sciences | E3: Fall 2026 | F3: From Northeastern. Rules showcase: C-, developmental math, P/F, 1-credit seminar, duplicate, CS Group C residency, 7-year-old course, incomplete syllabus | G3: =COUNTIF('Transcript Lines'!$B$2:$B$57,A3) | H3: =SUMIFS('Transcript Lines'!$M$2:$M$57,'Transcript Lines'!$B$2:$B$57,A3,'Transcript Lines'!$K$2:$K$57,"Matched*") | I3: =SUMIFS('Transcript Lines'!$J$2:$J$57,'Transcript Lines'!$B$2:$B$57,A3,'Transcript Lines'!$K$2:$K$57,"Maybe*")+SUMIFS('Transcript Lines'!$J$2:$J$57,'Transcript Lines'!$B$2:$B$57,A3,'Transcript Lines'!$K$2:$K$57,"Pending*") | J3: =COUNTIFS('Transcript Lines'!$B$2:$B$57,A3,'Transcript Lines'!$N$2:$N$57,"TX") | K3: jordan.reyes@example.edu | L3: 617-555-0122 | M3: 27 Thistlebrook Lane, Somerville, MA 02144 | N3: NEU
A4: SYN-24003 | B4: Aisha K. Bello | C4: Biology | D4: College of Arts & Sciences | E4: Fall 2026 | F4: From Northeastern. 5-credit lab courses; NU's one-semester general chemistry (maybe); research course; same-year conflicting decisions | G4: =COUNTIF('Transcript Lines'!$B$2:$B$57,A4) | H4: =SUMIFS('Transcript Lines'!$M$2:$M$57,'Transcript Lines'!$B$2:$B$57,A4,'Transcript Lines'!$K$2:$K$57,"Matched*") | I4: =SUMIFS('Transcript Lines'!$J$2:$J$57,'Transcript Lines'!$B$2:$B$57,A4,'Transcript Lines'!$K$2:$K$57,"Maybe*")+SUMIFS('Transcript Lines'!$J$2:$J$57,'Transcript Lines'!$B$2:$B$57,A4,'Transcript Lines'!$K$2:$K$57,"Pending*") | J4: =COUNTIFS('Transcript Lines'!$B$2:$B$57,A4,'Transcript Lines'!$N$2:$N$57,"TX") | K4: aisha.bello@example.edu | L4: 857-555-0163 | M4: 1190 Marrowind Avenue, Unit 2, Quincy, MA 02169 | N4: NEU
A5: SYN-24004 | B5: Liam O. Novak | C5: Economics | D5: College of Arts & Sciences | E5: Fall 2026 | F5: Northeastern then NYU (+ one non-accredited online school). 68-unit cap, ROTC, internship, superseded decision, prompt-injection syllabus, reuses Maya's approved course | G5: =COUNTIF('Transcript Lines'!$B$2:$B$57,A5) | H5: =SUMIFS('Transcript Lines'!$M$2:$M$57,'Transcript Lines'!$B$2:$B$57,A5,'Transcript Lines'!$K$2:$K$57,"Matched*") | I5: =SUMIFS('Transcript Lines'!$J$2:$J$57,'Transcript Lines'!$B$2:$B$57,A5,'Transcript Lines'!$K$2:$K$57,"Maybe*")+SUMIFS('Transcript Lines'!$J$2:$J$57,'Transcript Lines'!$B$2:$B$57,A5,'Transcript Lines'!$K$2:$K$57,"Pending*") | J5: =COUNTIFS('Transcript Lines'!$B$2:$B$57,A5,'Transcript Lines'!$N$2:$N$57,"TX") | K5: liam.novak@example.edu | L5: 646-555-0187 | M5: 62 Copperkettle Street, Apt 5F, Hoboken, NJ 07030 | N5: NYU
A7: Columns G-J are formulas over Transcript Lines. Units secured includes capped values; pending = units if approved.

Sheet Transcript Lines
A1: Line ID | B1: Student ID | C1: School | D1: Term | E1: Course code | F1: Title | G1: Credits | H1: Calendar | I1: Grade | J1: Units if approved | K1: Expected status | L1: Expected BU course | M1: Expected units | N1: Expected BU grade | O1: Expected reason code | P1: Flags | Q1: gt_counterpart | R1: gt_overlap_pct
A2: L-001 | B2: SYN-24001 | C2: NYU | D2: Fall 2024 | E2: PSYCH-UA 1 | F2: Intro to Psychology | G2: 4 | H2: Semester | I2: A- | J2: =IF(H2="Quarter",ROUND(G2*2/3,2),G2) | K2: Matched - existing equivalency | L2: CAS PS 101 | M2: 4 | N2: T | O2: EQ-CONTENT | Q2: CAS PS 101 | R2: 87
A3: L-002 | B3: SYN-24001 | C3: NYU | D3: Fall 2024 | E3: MATH-UA 121 | F3: Calculus I | G3: 4 | H3: Semester | I3: B+ | J3: =IF(H3="Quarter",ROUND(G3*2/3,2),G3) | K3: Matched - existing equivalency | L3: CAS MA 123 | M3: 4 | N3: T | O3: EQ-CONTENT | Q3: CAS MA 123 | R3: 100
A4: L-003 | B4: SYN-24001 | C4: NYU | D4: Fall 2024 | E4: ECON-UA 2 | F4: Introduction to Microeconomics | G4: 4 | H4: Semester | I4: B | J4: =IF(H4="Quarter",ROUND(G4*2/3,2),G4) | K4: Matched - existing equivalency | L4: CAS EC 101 | M4: 4 | N4: T | O4: EQ-CONTENT | Q4: CAS EC 101 | R4: 87
A5: L-004 | B5: SYN-24001 | C5: NYU | D5: Spring 2025 | E5: PSYCH-UA 10 | F5: Statistics for the Behavioral Sciences | G5: 4 | H5: Semester | I5: A | J5: =IF(H5="Quarter",ROUND(G5*2/3,2),G5) | K5: Maybe - syllabus on file; AI tier: Evaluator decides (50-79%) | M5: 0 | O5: PD-REVIEW | Q5: CAS PS 211 | R5: 75
A6: L-005 | B6: SYN-24001 | C6: NYU | D6: Spring 2025 | E6: PSYCH-UA 25 | F6: Cognitive Neuroscience | G6: 4 | H6: Semester | I6: B+ | J6: =IF(H6="Quarter",ROUND(G6*2/3,2),G6) | K6: Maybe - syllabus requested (TS) | M6: 0 | O6: PD-TS | Q6: CAS PS 231 | R6: 62
A7: L-006 | B7: SYN-24001 | C7: PSC | D7: Summer 2025 | E7: PSY 215 | F7: Psychology of Music | G7: 4 | H7: Quarter | I7: B | J7: =IF(H7="Quarter",ROUND(G7*2/3,2),G7) | K7: Matched - existing equivalency | L7: CAS PS 2TR | M7: 2.67 | N7: T | O7: EL-NOEQUIV
A8: L-007 | B8: SYN-24002 | C8: NEU | D8: Fall 2019 | E8: HIST 1130 | F8: Introduction to World History | G8: 4 | H8: Semester | I8: B | J8: =IF(H8="Quarter",ROUND(G8*2/3,2),G8) | K8: Pending - age review (5+ years old) | M8: 0 | O8: RV-AGE
A9: L-008 | B9: SYN-24002 | C9: NEU | D9: Fall 2023 | E9: CS 2000 | F9: Introduction to Program Design and Implementation | G9: 5 | H9: Semester | I9: A | J9: =IF(H9="Quarter",ROUND(G9*2/3,2),G9) | K9: Matched - existing equivalency | L9: CAS CS 111 | M9: 5 | N9: T | O9: EQ-CONTENT | Q9: CAS CS 111 | R9: 87
A10: L-009 | B10: SYN-24002 | C10: NEU | D10: Fall 2023 | E10: MATH 1341 | F10: Calculus 1 for Science and Engineering | G10: 4 | H10: Semester | I10: C- | J10: =IF(H10="Quarter",ROUND(G10*2/3,2),G10) | K10: Posted - no credit | L10: TFRGEN NOCRDT | M10: 0 | N10: TX | O10: NC-GRADE | Q10: CAS MA 123 | R10: 87
A11: L-010 | B11: SYN-24002 | C11: NEU | D11: Fall 2023 | E11: MATH 0990 | F11: Algebra Foundations (developmental) | G11: 4 | H11: Semester | I11: A | J11: =IF(H11="Quarter",ROUND(G11*2/3,2),G11) | K11: Posted - no credit | L11: TFRGEN NOCRDT | M11: 0 | N11: TX | O11: NC-REMEDIAL
A12: L-011 | B12: SYN-24002 | C12: NEU | D12: Fall 2023 | E12: PE 1100 | F12: Fitness Fundamentals | G12: 2 | H12: Semester | I12: P | J12: =IF(H12="Quarter",ROUND(G12*2/3,2),G12) | K12: Posted - no credit | L12: TFRGEN NOCRDT | M12: 0 | N12: TX | O12: NC-PE
A13: L-012 | B13: SYN-24002 | C13: NEU | D13: Fall 2023 | E13: FYS 1000 | F13: First-Year Seminar | G13: 1 | H13: Semester | I13: A | J13: =IF(H13="Quarter",ROUND(G13*2/3,2),G13) | K13: Posted - no credit | L13: TFRGEN NOCRDT | M13: 0 | N13: TX | O13: NC-ONECREDIT
A14: L-013 | B14: SYN-24002 | C14: NEU | D14: Spring 2024 | E14: CS 2100 | F14: Program Design and Implementation 1 | G14: 5 | H14: Semester | I14: B+ | J14: =IF(H14="Quarter",ROUND(G14*2/3,2),G14) | K14: Maybe - syllabus on file; AI tier: Evaluator decides (50-79%) | M14: 0 | O14: PD-REVIEW | Q14: CAS CS 112 | R14: 62
A15: L-014 | B15: SYN-24002 | C15: NEU | D15: Spring 2024 | E15: CS 1800 | F15: Discrete Structures | G15: 4 | H15: Semester | I15: B | J15: =IF(H15="Quarter",ROUND(G15*2/3,2),G15) | K15: Matched - existing equivalency | L15: CAS CS 131 | M15: 4 | N15: T | O15: EQ-CONTENT | Q15: CAS CS 131 | R15: 87
A16: L-015 | B16: SYN-24002 | C16: NEU | D16: Spring 2024 | E16: CS 1990 | F16: Introduction to Programming in Python | G16: 4 | H16: Semester | I16: A- | J16: =IF(H16="Quarter",ROUND(G16*2/3,2),G16) | K16: Matched - existing equivalency | L16: CAS CS 1TR | M16: 4 | N16: T | O16: EL-DUPLICATE | Q16: CAS CS 111 | R16: 75
A17: L-016 | B17: SYN-24002 | C17: NEU | D17: Spring 2024 | E17: FILM 1101 | F17: Film Analysis | G17: 4 | H17: Semester | I17: P | J17: =IF(H17="Quarter",ROUND(G17*2/3,2),G17) | K17: Posted - no credit | L17: TFRGEN NOCRDT | M17: 0 | N17: TX | O17: NC-PASSFAIL
A18: L-017 | B18: SYN-24002 | C18: NEU | D18: Fall 2024 | E18: CS 2700 | F18: Data Structures and Analysis | G18: 5 | H18: Semester | I18: B | J18: =IF(H18="Quarter",ROUND(G18*2/3,2),G18) | K18: Maybe - syllabus incomplete (TM request) | M18: 0 | O18: PD-TM | Q18: CAS CS 112 | R18: 75
A19: L-018 | B19: SYN-24002 | C19: NEU | D19: Fall 2024 | E19: CS 3650 | F19: Computer Systems | G19: 4 | H19: Semester | I19: B | J19: =IF(H19="Quarter",ROUND(G19*2/3,2),G19) | K19: Matched - existing equivalency | L19: CAS CS 210 | M19: 4 | N19: T | O19: EQ-CONTENT | Q19: CAS CS 210 | R19: 100
A20: L-019 | B20: SYN-24002 | C20: NEU | D20: Fall 2024 | E20: CS 4400 | F20: Programming Languages | G20: 4 | H20: Semester | I20: A- | J20: =IF(H20="Quarter",ROUND(G20*2/3,2),G20) | K20: Matched - existing equivalency | L20: CAS CS 2TR | M20: 4 | N20: T | O20: EL-RESIDENCY | Q20: CAS CS 320 | R20: 100
A21: L-020 | B21: SYN-24002 | C21: NEU | D21: Fall 2024 | E21: MATH 2331 | F21: Linear Algebra | G21: 4 | H21: Semester | I21: B+ | J21: =IF(H21="Quarter",ROUND(G21*2/3,2),G21) | K21: Matched - existing equivalency | L21: CAS MA 242 | M21: 4 | N21: T | O21: EQ-CONTENT | Q21: CAS MA 242 | R21: 100
A22: L-021 | B22: SYN-24003 | C22: NEU | D22: Fall 2024 | E22: BIOL 1107 | F22: Foundations of Biology | G22: 5 | H22: Semester | I22: A | J22: =IF(H22="Quarter",ROUND(G22*2/3,2),G22) | K22: Matched - existing equivalency | L22: CAS BI 107 | M22: 5 | N22: T | O22: EQ-CONTENT | Q22: CAS BI 107 | R22: 87
A23: L-022 | B23: SYN-24003 | C23: NEU | D23: Fall 2024 | E23: CHEM 1161 | F23: General Chemistry for Science Majors | G23: 5 | H23: Semester | I23: B+ | J23: =IF(H23="Quarter",ROUND(G23*2/3,2),G23) | K23: Maybe - syllabus on file; AI tier: Evaluator decides (50-79%) | M23: 0 | O23: PD-REVIEW | Q23: CAS CH 101 | R23: 62
A24: L-023 | B24: SYN-24003 | C24: NEU | D24: Fall 2024 | E24: ENGW 1111 | F24: First-Year Writing | G24: 4 | H24: Semester | I24: A- | J24: =IF(H24="Quarter",ROUND(G24*2/3,2),G24) | K24: Matched - existing equivalency | L24: TFRGEN 1TR | M24: 4 | N24: T | O24: EL-NOEQUIV
A25: L-024 | B25: SYN-24003 | C25: NEU | D25: Spring 2025 | E25: BIOL 1113 | F25: General Biology 2 | G25: 4 | H25: Semester | I25: B+ | J25: =IF(H25="Quarter",ROUND(G25*2/3,2),G25) | K25: Matched - existing equivalency | L25: CAS BI 108 | M25: 4 | N25: T | O25: EQ-CONTENT | Q25: CAS BI 108 | R25: 100
A26: L-025 | B26: SYN-24003 | C26: NEU | D26: Spring 2025 | E26: MATH 1341 | F26: Calculus 1 for Science and Engineering | G26: 4 | H26: Semester | I26: A | J26: =IF(H26="Quarter",ROUND(G26*2/3,2),G26) | K26: Matched - existing equivalency | L26: CAS MA 123 | M26: 4 | N26: T | O26: EQ-CONTENT | Q26: CAS MA 123 | R26: 87
A27: L-026 | B27: SYN-24003 | C27: NEU | D27: Spring 2025 | E27: BIOL 2299 | F27: Inquiries in Biological Sciences | G27: 4 | H27: Semester | I27: B | J27: =IF(H27="Quarter",ROUND(G27*2/3,2),G27) | K27: Maybe - syllabus on file; AI tier: Elective (<50%) | M27: 0 | O27: PD-REVIEW | Q27: CAS BI 107 | R27: 37
A28: L-027 | B28: SYN-24003 | C28: NEU | D28: Fall 2025 | E28: BIOL 2301 | F28: Genetics and Molecular Biology | G28: 5 | H28: Semester | I28: B+ | J28: =IF(H28="Quarter",ROUND(G28*2/3,2),G28) | K28: Maybe - syllabus on file; AI tier: Evaluator decides (50-79%) | M28: 0 | O28: PD-REVIEW | Q28: CAS BI 206 | R28: 75
A29: L-028 | B29: SYN-24003 | C29: NEU | D29: Fall 2025 | E29: CHEM 2311 | F29: Organic Chemistry 1 | G29: 5 | H29: Semester | I29: C+ | J29: =IF(H29="Quarter",ROUND(G29*2/3,2),G29) | K29: Maybe - syllabus requested (TS) | M29: 0 | O29: PD-TS | Q29: CAS CH 203 | R29: 87
A30: L-029 | B30: SYN-24003 | C30: NEU | D30: Fall 2025 | E30: BIOL 2703 | F30: Microbiology | G30: 5 | H30: Semester | I30: A- | J30: =IF(H30="Quarter",ROUND(G30*2/3,2),G30) | K30: Matched - existing equivalency | L30: CAS BI 2TR | M30: 5 | N30: T | O30: EL-PARTIAL | P30: CONFLICT: same catalog year, different decisions -> flag for department | Q30: CAS BI 210 | R30: 87
A31: L-030 | B31: SYN-24003 | C31: NEU | D31: Spring 2026 | E31: BIOL 3611 | F31: Biochemistry | G31: 5 | H31: Semester | I31: B+ | J31: =IF(H31="Quarter",ROUND(G31*2/3,2),G31) | K31: Maybe - syllabus on file; AI tier: Equivalent (>=80%) | M31: 0 | O31: PD-REVIEW | Q31: CAS CH 373 | R31: 87
A32: L-031 | B32: SYN-24003 | C32: NEU | D32: Spring 2026 | E32: CHEM 2313 | F32: Organic Chemistry 2 | G32: 5 | H32: Semester | I32: B | J32: =IF(H32="Quarter",ROUND(G32*2/3,2),G32) | K32: Matched - existing equivalency | L32: CAS CH 204 | M32: 5 | N32: T | O32: EQ-CONTENT | Q32: CAS CH 204 | R32: 100
A33: L-032 | B33: SYN-24003 | C33: NEU | D33: Spring 2026 | E33: BIOL 4990 | F33: Directed Research in Biology | G33: 4 | H33: Semester | I33: A | J33: =IF(H33="Quarter",ROUND(G33*2/3,2),G33) | K33: Posted - no credit | L33: TFRGEN NOCRDT | M33: 0 | N33: TX | O33: NC-RESEARCH
A34: L-033 | B34: SYN-24004 | C34: NEU | D34: Fall 2022 | E34: ECON 1116 | F34: Principles of Microeconomics | G34: 4 | H34: Semester | I34: A | J34: =IF(H34="Quarter",ROUND(G34*2/3,2),G34) | K34: Matched - existing equivalency | L34: CAS EC 101 | M34: 4 | N34: T | O34: EQ-CONTENT | Q34: CAS EC 101 | R34: 87
A35: L-034 | B35: SYN-24004 | C35: NEU | D35: Fall 2022 | E35: MATH 1341 | F35: Calculus 1 for Science and Engineering | G35: 4 | H35: Semester | I35: B | J35: =IF(H35="Quarter",ROUND(G35*2/3,2),G35) | K35: Matched - existing equivalency | L35: CAS MA 123 | M35: 4 | N35: T | O35: EQ-CONTENT | Q35: CAS MA 123 | R35: 87
A36: L-035 | B36: SYN-24004 | C36: NEU | D36: Fall 2022 | E36: ENGW 1111 | F36: First-Year Writing | G36: 4 | H36: Semester | I36: A- | J36: =IF(H36="Quarter",ROUND(G36*2/3,2),G36) | K36: Matched - existing equivalency | L36: TFRGEN 1TR | M36: 4 | N36: T | O36: EL-NOEQUIV
A37: L-036 | B37: SYN-24004 | C37: NEU | D37: Fall 2022 | E37: MILS 1101 | F37: Military Science I (ROTC) | G37: 2 | H37: Semester | I37: A | J37: =IF(H37="Quarter",ROUND(G37*2/3,2),G37) | K37: Posted - no credit | L37: TFRGEN NOCRDT | M37: 0 | N37: TX | O37: NC-ROTC
A38: L-037 | B38: SYN-24004 | C38: NEU | D38: Spring 2023 | E38: ECON 1115 | F38: Principles of Macroeconomics | G38: 4 | H38: Semester | I38: B+ | J38: =IF(H38="Quarter",ROUND(G38*2/3,2),G38) | K38: Matched - existing equivalency | L38: CAS EC 102 | M38: 4 | N38: T | O38: EQ-CONTENT | Q38: CAS EC 102 | R38: 100
A39: L-038 | B39: SYN-24004 | C39: NEU | D39: Spring 2023 | E39: MATH 1342 | F39: Calculus 2 for Science and Engineering | G39: 4 | H39: Semester | I39: B- | J39: =IF(H39="Quarter",ROUND(G39*2/3,2),G39) | K39: Matched - existing equivalency | L39: CAS MA 124 | M39: 4 | N39: T | O39: EQ-CONTENT | Q39: CAS MA 124 | R39: 87
A40: L-039 | B40: SYN-24004 | C40: NEU | D40: Spring 2023 | E40: HIST 1130 | F40: Introduction to World History | G40: 4 | H40: Semester | I40: B | J40: =IF(H40="Quarter",ROUND(G40*2/3,2),G40) | K40: Matched - existing equivalency | L40: TFRGEN 1TR | M40: 4 | N40: T | O40: EL-NOEQUIV
...

Sheet BU Courses
A1: BU code | B1: Dept | C1: Title | D1: Program | E1: Requirement type | F1: Level | G1: Credits | H1: Residency rule | I1: Source | J1: Description | K1: Learning outcomes | L1: Topics
A2: CAS CS 111 | B2: CS | C2: Introduction to Computer Science 1 | D2: Computer Science | E2: Core (Group A) | F2: 100 | G2: 4 | I2: Code/title from provided BU workbook (public catalog); description synthetic | J2: Introduction to Computer Science 1 is an introductory course in computer science. It covers variables and expressions, conditionals and loops, functions and parameters and lists and strings, and builds toward recursion and file input and output. Students work through programming assignments, with later units on debugging and testing and problem decomposition. | K2: Explain the core ideas of variables and expressions | Apply conditionals and loops to solve standard problems | Analyze problems involving functions and parameters | Use lists and strings in practical exercises | Evaluate approaches to recursion | Communicate findings about file input and output | L2: variables and expressions | conditionals and loops | functions and parameters | lists and strings | recursion | file input and output | debugging and testing | problem decomposition
A3: CAS CS 112 | B3: CS | C3: Introduction to Computer Science 2 | D3: Computer Science | E3: Core (Group A) | F3: 100 | G3: 4 | I3: Code/title from provided BU workbook (public catalog); description synthetic | J3: Introduction to Computer Science 2 is an introductory course in computer science. It covers object-oriented programming, linked lists, stacks and queues and binary trees, and builds toward hash tables and sorting algorithms. Students work through programming assignments, with later units on algorithm efficiency and recursion on data structures. | K3: Explain the core ideas of object-oriented programming | Apply linked lists to solve standard problems | Analyze problems involving stacks and queues | Use binary trees in practical exercises | Evaluate approaches to hash tables | Communicate findings about sorting algorithms | L3: object-oriented programming | linked lists | stacks and queues | binary trees | hash tables | sorting algorithms | algorithm efficiency | recursion on data structures
A4: CAS CS 131 | B4: CS | C4: Combinatoric Structures | D4: Computer Science | E4: Core (Group A) | F4: 100 | G4: 4 | I4: Code/title from provided BU workbook (public catalog); description synthetic | J4: Combinatoric Structures is an introductory course in computer science. It covers propositional logic, proof techniques, sets and functions and counting principles, and builds toward mathematical induction and relations. Students work through programming assignments, with later units on graph basics and discrete probability. | K4: Explain the core ideas of propositional logic | Apply proof techniques to solve standard problems | Analyze problems involving sets and functions | Use counting principles in practical exercises | Evaluate approaches to mathematical induction | Communicate findings about relations | L4: propositional logic | proof techniques | sets and functions | counting principles | mathematical induction | relations | graph basics | discrete probability
A5: CAS CS 210 | B5: CS | C5: Computer Systems | D5: Computer Science | E5: Core (Group A) | F5: 200 | G5: 4 | I5: Code/title from provided BU workbook (public catalog); description synthetic | J5: Computer Systems is an intermediate course in computer science. It covers binary data representation, C programming, assembly language and memory hierarchy, and builds toward caches and linking and loading. Students work through programming assignments, with later units on processes and virtual memory. | K5: Explain the core ideas of binary data representation | Apply C programming to solve standard problems | Analyze problems involving assembly language | Use memory hierarchy in practical exercises | Evaluate approaches to caches | Communicate findings about linking and loading | L5: binary data representation | C programming | assembly language | memory hierarchy | caches | linking and loading | processes | virtual memory
A6: CAS CS 330 | B6: CS | C6: Introduction to the Analysis of Algorithms | D6: Computer Science | E6: Core (Group A) | F6: 300 | G6: 4 | I6: Code/title from provided BU workbook (public catalog); description synthetic | J6: Introduction to the Analysis of Algorithms is an advanced course in computer science. It covers asymptotic analysis, divide and conquer, greedy algorithms and dynamic programming, and builds toward graph algorithms and shortest paths. Students work through programming assignments, with later units on network flow and NP-completeness. | K6: Explain the core ideas of asymptotic analysis | Apply divide and conquer to solve standard problems | Analyze problems involving greedy algorithms | Use dynamic programming in practical exercises | Evaluate approaches to graph algorithms | Communicate findings about shortest paths | L6: asymptotic analysis | divide and conquer | greedy algorithms | dynamic programming | graph algorithms | shortest paths | network flow | NP-completeness
A7: CAS CS 132 | B7: CS | C7: Geometric Algorithms | D7: Computer Science | E7: Group B (choose) | F7: 100 | G7: 4 | I7: Code/title from provided BU workbook (public catalog); description synthetic | J7: Geometric Algorithms is an introductory course in computer science. It covers vectors and matrices, linear systems, matrix factorization and eigenvalues, and builds toward least squares and geometric transformations. Students work through programming assignments, with later units on singular value decomposition and computational geometry. | K7: Explain the core ideas of vectors and matrices | Apply linear systems to solve standard problems | Analyze problems involving matrix factorization | Use eigenvalues in practical exercises | Evaluate approaches to least squares | Communicate findings about geometric transformations | L7: vectors and matrices | linear systems | matrix factorization | eigenvalues | least squares | geometric transformations | singular value decomposition | computational geometry
A8: CAS CS 235 | B8: CS | C8: Algebraic Algorithms | D8: Computer Science | E8: Group B (choose) | F8: 200 | G8: 4 | I8: Code/title from provided BU workbook (public catalog); description synthetic | J8: Algebraic Algorithms is an intermediate course in computer science. It covers modular arithmetic, groups and rings, polynomials and finite fields, and builds toward public-key cryptography and error-correcting codes. Students work through programming assignments, with later units on number-theoretic algorithms and fast Fourier transform. | K8: Explain the core ideas of modular arithmetic | Apply groups and rings to solve standard problems | Analyze problems involving polynomials | Use finite fields in practical exercises | Evaluate approaches to public-key cryptography | Communicate findings about error-correcting codes | L8: modular arithmetic | groups and rings | polynomials | finite fields | public-key cryptography | error-correcting codes | number-theoretic algorithms | fast Fourier transform
A9: CAS CS 237 | B9: CS | C9: Probability in Computing | D9: Computer Science | E9: Group B (choose) | F9: 200 | G9: 4 | I9: Code/title from provided BU workbook (public catalog); description synthetic | J9: Probability in Computing is an intermediate course in computer science. It covers probability axioms, random variables, expectation and variance and common distributions, and builds toward Markov chains and randomized algorithms. Students work through programming assignments, with later units on tail bounds and simulation. | K9: Explain the core ideas of probability axioms | Apply random variables to solve standard problems | Analyze problems involving expectation and variance | Use common distributions in practical exercises | Evaluate approaches to Markov chains | Communicate findings about randomized algorithms | L9: probability axioms | random variables | expectation and variance | common distributions | Markov chains | randomized algorithms | tail bounds | simulation
A10: CAS CS 320 | B10: CS | C10: Concepts of Programming Languages | D10: Computer Science | E10: Group C (BU only) | F10: 300 | G10: 4 | H10: CS Group C: must be taken at BU (requirement blocked; units may post as elective) | I10: Code/title from provided BU workbook (public catalog); description synthetic | J10: Concepts of Programming Languages is an advanced course in computer science. It covers syntax and grammars, interpreters, type systems and functional programming, and builds toward scoping and binding and parsing. Students work through programming assignments, with later units on semantics and language paradigms. | K10: Explain the core ideas of syntax and grammars | Apply interpreters to solve standard problems | Analyze problems involving type systems | Use functional programming in practical exercises | Evaluate approaches to scoping and binding | Communicate findings about parsing | L10: syntax and grammars | interpreters | type systems | functional programming | scoping and binding | parsing | semantics | language paradigms
A11: CAS CS 332 | B11: CS | C11: Elements of the Theory of Computation | D11: Computer Science | E11: Group C (BU only) | F11: 300 | G11: 4 | H11: CS Group C: must be taken at BU (requirement blocked; units may post as elective) | I11: Code/title from provided BU workbook (public catalog); description synthetic | J11: Elements of the Theory of Computation is an advanced course in computer science. It covers finite automata, regular languages, context-free grammars and pushdown automata, and builds toward Turing machines and decidability. Students work through programming assignments, with later units on reductions and complexity classes. | K11: Explain the core ideas of finite automata | Apply regular languages to solve standard problems | Analyze problems involving context-free grammars | Use pushdown automata in practical exercises | Evaluate approaches to Turing machines | Communicate findings about decidability | L11: finite automata | regular languages | context-free grammars | pushdown automata | Turing machines | decidability | reductions | complexity classes
A12: CAS CS 350 | B12: CS | C12: Fundamentals of Computing Systems | D12: Computer Science | E12: Group C (BU only) | F12: 300 | G12: 4 | H12: CS Group C: must be taken at BU (requirement blocked; units may post as elective) | I12: Code/title from provided BU workbook (public catalog); description synthetic | J12: Fundamentals of Computing Systems is an advanced course in computer science. It covers concurrency, scheduling, synchronization and queueing models, and builds toward performance analysis and operating system design. Students work through programming assignments, with later units on resource management and distributed coordination. | K12: Explain the core ideas of concurrency | Apply scheduling to solve standard problems | Analyze problems involving synchronization | Use queueing models in practical exercises | Evaluate approaches to performance analysis | Communicate findings about operating system design | L12: concurrency | scheduling | synchronization | queueing models | performance analysis | operating system design | resource management | distributed coordination
A13: CAS CS 103 | B13: CS | C13: Introduction to Internet Technologies | D13: Computer Science | E13: Elective | F13: 100 | G13: 4 | I13: Fully synthetic course (not a real BU offering) | J13: Introduction to Internet Technologies is an introductory course in computer science. It covers how the internet works, HTML, CSS and web hosting, and builds toward client-server model and basic JavaScript. Students work through programming assignments, with later units on web accessibility and online privacy. | K13: Explain the core ideas of how the internet works | Apply HTML to solve standard problems | Analyze problems involving CSS | Use web hosting in practical exercises | Evaluate approaches to client-server model | Communicate findings about basic JavaScript | L13: how the internet works | HTML | CSS | web hosting | client-server model | basic JavaScript | web accessibility | online privacy
A14: CAS CS 108 | B14: CS | C14: Programming with Python | D14: Computer Science | E14: Elective | F14: 100 | G14: 4 | I14: Fully synthetic course (not a real BU offering) | J14: Programming with Python is an introductory course in computer science. It covers Python syntax, control flow, functions and lists and dictionaries, and builds toward modules and libraries and file processing. Students work through programming assignments, with later units on data visualization and scripting automation. | K14: Explain the core ideas of Python syntax | Apply control flow to solve standard problems | Analyze problems involving functions | Use lists and dictionaries in practical exercises | Evaluate approaches to modules and libraries | Communicate findings about file processing | L14: Python syntax | control flow | functions | lists and dictionaries | modules and libraries | file processing | data visualization | scripting automation
A15: CAS CS 115 | B15: CS | C15: Introduction to Data Science | D15: Computer Science | E15: Elective | F15: 100 | G15: 4 | I15: Fully synthetic course (not a real BU offering) | J15: Introduction to Data Science is an introductory course in computer science. It covers data collection, data cleaning, exploratory analysis and data visualization, and builds toward descriptive statistics and regression basics. Students work through programming assignments, with later units on Python notebooks and data ethics. | K15: Explain the core ideas of data collection | Apply data cleaning to solve standard problems | Analyze problems involving exploratory analysis | Use data visualization in practical exercises | Evaluate approaches to descriptive statistics | Communicate findings about regression basics | L15: data collection | data cleaning | exploratory analysis | data visualization | descriptive statistics | regression basics | Python notebooks | data ethics
A16: CAS CS 122 | B16: CS | C16: Web Development Foundations | D16: Computer Science | E16: Elective | F16: 100 | G16: 4 | I16: Fully synthetic course (not a real BU offering) | J16: Web Development Foundations is an introductory course in computer science. It covers HTML, CSS, JavaScript and DOM manipulation, and builds toward responsive design and forms and validation. Students work through programming assignments, with later units on HTTP basics and version control. | K16: Explain the core ideas of HTML | Apply CSS to solve standard problems | Analyze problems involving JavaScript | Use DOM manipulation in practical exercises | Evaluate approaches to responsive design | Communicate findings about forms and validation | L16: HTML | CSS | JavaScript | DOM manipulation | responsive design | forms and validation | HTTP basics | version control
A17: CAS CS 140 | B17: CS | C17: Introduction to Cybersecurity | D17: Computer Science | E17: Elective | F17: 100 | G17: 4 | I17: Fully synthetic course (not a real BU offering) | J17: Introduction to Cybersecurity is an introductory course in computer science. It covers threat models, cryptography basics, authentication and network attacks, and builds toward malware and secure coding. Students work through programming assignments, with later units on security policy and incident response. | K17: Explain the core ideas of threat models | Apply cryptography basics to solve standard problems | Analyze problems involving authentication | Use network attacks in practical exercises | Evaluate approaches to malware | Communicate findings about secure coding | L17: threat models | cryptography basics | authentication | network attacks | malware | secure coding | security policy | incident response
A18: CAS CS 211 | B18: CS | C18: Object-Oriented Software Design | D18: Computer Science | E18: Elective | F18: 200 | G18: 4 | I18: Fully synthetic course (not a real BU offering) | J18: Object-Oriented Software Design is an intermediate course in computer science. It covers object-oriented programming, classes and interfaces, inheritance and design patterns, and builds toward UML modeling and unit testing. Students work through programming assignments, with later units on refactoring and version control. | K18: Explain the core ideas of object-oriented programming | Apply classes and interfaces to solve standard problems | Analyze problems involving inheritance | Use design patterns in practical exercises | Evaluate approaches to UML modeling | Communicate findings about unit testing | L18: object-oriented programming | classes and interfaces | inheritance | design patterns | UML modeling | unit testing | refactoring | version control
A19: CAS CS 216 | B19: CS | C19: Database Systems | D19: Computer Science | E19: Elective | F19: 200 | G19: 4 | I19: Fully synthetic course (not a real BU offering) | J19: Database Systems is an intermediate course in computer science. It covers relational model, SQL queries, entity-relationship design and normalization, and builds toward indexing and transactions. Students work through programming assignments, with later units on query optimization and NoSQL databases. | K19: Explain the core ideas of relational model | Apply SQL queries to solve standard problems | Analyze problems involving entity-relationship design | Use normalization in practical exercises | Evaluate approaches to indexing | Communicate findings about transactions | L19: relational model | SQL queries | entity-relationship design | normalization | indexing | transactions | query optimization | NoSQL databases
A20: CAS CS 225 | B20: CS | C20: Computer Networks Fundamentals | D20: Computer Science | E20: Elective | F20: 200 | G20: 4 | I20: Fully synthetic course (not a real BU offering) | J20: Computer Networks Fundamentals is an intermediate course in computer science. It covers network layers, TCP and UDP, IP addressing and routing, and builds toward the web and HTTP and wireless networks. Students work through programming assignments, with later units on network security and socket programming. | K20: Explain the core ideas of network layers | Apply TCP and UDP to solve standard problems | Analyze problems involving IP addressing | Use routing in practical exercises | Evaluate approaches to the web and HTTP | Communicate findings about wireless networks | L20: network layers | TCP and UDP | IP addressing | routing | the web and HTTP | wireless networks | network security | socket programming
A21: CAS CS 236 | B21: CS | C21: Information Security | D21: Computer Science | E21: Elective | F21: 200 | G21: 4 | I21: Fully synthetic course (not a real BU offering) | J21: Information Security is an intermediate course in computer science. It covers cryptography basics, access control, authentication and software vulnerabilities, and builds toward network attacks and secure coding. Students work through programming assignments, with later units on privacy and security policy. | K21: Explain the core ideas of cryptography basics | Apply access control to solve standard problems | Analyze problems involving authentication | Use software vulnerabilities in practical exercises | Evaluate approaches to network attacks | Communicate findings about secure coding | L21: cryptography basics | access control | authentication | software vulnerabilities | network attacks | secure coding | privacy | security policy
A22: CAS CS 240 | B22: CS | C22: Introduction to Machine Learning | D22: Computer Science | E22: Elective | F22: 200 | G22: 4 | I22: Fully synthetic course (not a real BU offering) | J22: Introduction to Machine Learning is an intermediate course in computer science. It covers supervised learning, linear regression, classification and model evaluation, and builds toward overfitting and regularization and clustering. Students work through programming assignments, with later units on neural networks and feature engineering. | K22: Explain the core ideas of supervised learning | Apply linear regression to solve standard problems | Analyze problems involving classification | Use model evaluation in practical exercises | Evaluate approaches to overfitting and regularization | Communicate findings about clustering | L22: supervised learning | linear regression | classification | model evaluation | overfitting and regularization | clustering | neural networks | feature engineering
A23: CAS CS 251 | B23: CS | C23: Mobile App Development | D23: Computer Science | E23: Elective | F23: 200 | G23: 4 | I23: Fully synthetic course (not a real BU offering) | J23: Mobile App Development is an intermediate course in computer science. It covers mobile platforms, user interface layout, event handling and local storage, and builds toward networking APIs and app lifecycle. Students work through programming assignments, with later units on testing on devices and app deployment. | K23: Explain the core ideas of mobile platforms | Apply user interface layout to solve standard problems | Analyze problems involving event handling | Use local storage in practical exercises | Evaluate approaches to networking APIs | Communicate findings about app lifecycle | L23: mobile platforms | user interface layout | event handling | local storage | networking APIs | app lifecycle | testing on devices | app deployment
A24: CAS CS 280 | B24: CS | C24: Human-Computer Interaction | D24: Computer Science | E24: Elective | F24: 200 | G24: 4 | I24: Fully synthetic course (not a real BU offering) | J24: Human-Computer Interaction is an intermediate course in computer science. It covers user-centered design, usability testing, prototyping and interaction design, and builds toward accessibility and cognitive models. Students work through programming assignments, with later units on visual design and user research. | K24: Explain the core ideas of user-centered design | Apply usability testing to solve standard problems | Analyze problems involving prototyping | Use interaction design in practical exercises | Evaluate approaches to accessibility | Communicate findings about cognitive models | L24: user-centered design | usability testing | prototyping | interaction design | accessibility | cognitive models | visual design | user research
... A33: CAS EC 102 | B33: EC | C33: Introductory Macroeconomic Analysis | D33: Economics | E33: Intro | F33: 100 | G33: 4 | I33: Code/title from provided BU workbook (public catalog); description synthetic | J33: Introductory Macroeconomic Analysis is an introductory course in economics. It covers GDP measurement, unemployment, inflation and aggregate demand and supply, and builds toward fiscal policy and monetary policy. Students work through data and policy exercises, with later units on economic growth and international trade basics. | K33: Explain the core ideas of GDP measurement | Apply unemployment to solve standard problems | Analyze problems involving inflation | Use aggregate demand and supply in practical exercises | Evaluate approaches to fiscal policy | Communicate findings about monetary policy | L33: GDP measurement | unemployment | inflation | aggregate demand and supply | fiscal policy | monetary policy | economic growth | international trade basics
A34: CAS EC 201 | B34: EC | C34: Intermediate Microeconomic Analysis | D34: Economics | E34: Core (200+ cap) | F34: 200 | G34: 4 | H34: Economics: max four 200+ level courses transferred after matriculation | I34: Code/title from provided BU workbook (public catalog); description synthetic | J34: Intermediate Microeconomic Analysis is an intermediate course in economics. It covers consumer theory, utility maximization, producer theory and cost minimization, and builds toward general equilibrium and welfare economics. Students work through data and policy exercises, with later units on game theory basics and market structures. | K34: Explain the core ideas of consumer theory | Apply utility maximization to solve standard problems | Analyze problems involving producer theory | Use cost minimization in practical exercises | Evaluate approaches to general equilibrium | Communicate findings about welfare economics | L34: consumer theory | utility maximization | producer theory | cost minimization | general equilibrium | welfare economics | game theory basics | market structures
A35: CAS EC 202 | B35: EC | C35: Intermediate Macroeconomic Analysis | D35: Economics | E35: Core (200+ cap) | F35: 200 | G35: 4 | H35: Economics: max four 200+ level courses transferred after matriculation | I35: Code/title from provided BU workbook (public catalog); description synthetic | J35: Intermediate Macroeconomic Analysis is an intermediate course in economics. It covers long-run growth models, IS-LM model, labor markets and consumption and saving, and builds toward investment and open-economy macroeconomics. Students work through data and policy exercises, with later units on monetary policy rules and business cycles. | K35: Explain the core ideas of long-run growth models | Apply IS-LM model to solve standard problems | Analyze problems involving labor markets | Use consumption and saving in practical exercises | Evaluate approaches to investment | Communicate findings about open-economy macroeconomics | L35: long-run growth models | IS-LM model | labor markets | consumption and saving | investment | open-economy macroeconomics | monetary policy rules | business cycles
A36: CAS EC 203 | B36: EC | C36: Empirical Economics 1 | D36: Economics | E36: Core (200+ cap) | F36: 200 | G36: 4 | H36: Economics: max four 200+ level courses transferred after matriculation | I36: Code/title from provided BU workbook (public catalog); description synthetic | J36: Empirical Economics 1 is an intermediate course in economics. It covers descriptive statistics, probability distributions, sampling and confidence intervals, and builds toward hypothesis testing and simple regression. Students work through data and policy exercises, with later units on statistical software and data interpretation. | K36: Explain the core ideas of descriptive statistics | Apply probability distributions to solve standard problems | Analyze problems involving sampling | Use confidence intervals in practical exercises | Evaluate approaches to hypothesis testing | Communicate findings about simple regression | L36: descriptive statistics | probability distributions | sampling | confidence intervals | hypothesis testing | simple regression | statistical software | data interpretation
A37: CAS EC 204 | B37: EC | C37: Empirical Economics 2 | D37: Economics | E37: Core (200+ cap) | F37: 200 | G37: 4 | H37: Economics: max four 200+ level courses transferred after matriculation | I37: Code/title from provided BU workbook (public catalog); description synthetic | J37: Empirical Economics 2 is an intermediate course in economics. It covers multiple regression, omitted variable bias, dummy variables and heteroskedasticity, and builds toward instrumental variables and panel data. Students work through data and policy exercises, with later units on causal inference and statistical software. | K37: Explain the core ideas of multiple regression | Apply omitted variable bias to solve standard problems | Analyze problems involving dummy variables | Use heteroskedasticity in practical exercises | Evaluate approaches to instrumental variables | Communicate findings about panel data | L37: multiple regression | omitted variable bias | dummy variables | heteroskedasticity | instrumental variables | panel data | causal inference | statistical software
A38: CAS EC 110 | B38: EC | C38: Economics of Everyday Life | D38: Economics | E38: Elective | F38: 100 | G38: 4 | I38: Fully synthetic course (not a real BU offering) | J38: Economics of Everyday Life is an introductory course in economics. It covers opportunity cost, incentives, personal finance and housing markets, and builds toward labor markets and health care choices. Students work through data and policy exercises, with later units on behavioral biases and public policy. | K38: Explain the core ideas of opportunity cost | Apply incentives to solve standard problems | Analyze problems involving personal finance | Use housing markets in practical exercises | Evaluate approaches to labor markets | Communicate findings about health care choices | L38: opportunity cost | incentives | personal finance | housing markets | labor markets | health care choices | behavioral biases | public policy
A39: CAS EC 220 | B39: EC | C39: Money and Banking | D39: Economics | E39: Elective (200+ cap) | F39: 200 | G39: 4 | H39: Economics: max four 200+ level courses transferred after matriculation | I39: Fully synthetic course (not a real BU offering) | J39: Money and Banking is an intermediate course in economics. It covers money supply, banking system, central banking and interest rates, and builds toward financial markets and monetary policy. Students work through data and policy exercises, with later units on financial crises and bank regulation. | K39: Explain the core ideas of money supply | Apply banking system to solve standard problems | Analyze problems involving central banking | Use interest rates in practical exercises | Evaluate approaches to financial markets | Communicate findings about monetary policy | L39: money supply | banking system | central banking | interest rates | financial markets | monetary policy | financial crises | bank regulation
A40: CAS EC 230 | B40: EC | C40: Public Finance | D40: Economics | E40: Elective (200+ cap) | F40: 200 | G40: 4 | H40: Economics: max four 200+ level courses transferred after matriculation | I40: Fully synthetic course (not a real BU offering) | J40: Public Finance is an intermediate course in economics. It covers public goods, externalities, taxation and tax incidence, and builds toward social insurance and government spending. Students work through data and policy exercises, with later units on cost-benefit analysis and fiscal federalism. | K40: Explain the core ideas of public goods | Apply externalities to solve standard problems | Analyze problems involving taxation | Use tax incidence in practical exercises | Evaluate approaches to social insurance | Communicate findings about government spending | L40: public goods | externalities | taxation | tax incidence | social insurance | government spending | cost-benefit analysis | fiscal federalism
A41: CAS EC 240 | B41: EC | C41: Labor Economics | D41: Economics | E41: Elective (200+ cap) | F41: 200 | G41: 4 | H41: Economics: max four 200+ level courses transferred after matriculation | I41: Fully synthetic course (not a real BU offering) | J41: Labor Economics is an intermediate course in economics. It covers labor supply, labor demand, wage determination and human capital, and builds toward discrimination and unions. Students work through data and policy exercises, with later units on minimum wage and unemployment. | K41: Explain the core ideas of labor supply | Apply labor demand to solve standard problems | Analyze problems involving wage determination | Use human capital in practical exercises | Evaluate approaches to discrimination | Communicate findings about unions | L41: labor supply | labor demand | wage determination | human capital | discrimination | unions | minimum wage | unemployment
A42: CAS EC 250 | B42: EC | C42: International Trade | D42: Economics | E42: Elective (200+ cap) | F42: 200 | G42: 4 | H42: Economics: max four 200+ level courses transferred after matriculation | I42: Fully synthetic course (not a real BU offering) | J42: International Trade is an intermediate course in economics. It covers comparative advantage, trade models, tariffs and quotas and trade agreements, and builds toward globalization and exchange rates. Students work through data and policy exercises, with later units on trade and inequality and multinational firms. | K42: Explain the core ideas of comparative advantage | Apply trade models to solve standard problems | Analyze problems involving tariffs and quotas | Use trade agreements in practical exercises | Evaluate approaches to globalization | Communicate findings about exchange rates | L42: comparative advantage | trade models | tariffs and quotas | trade agreements | globalization | exchange rates | trade and inequality | multinational firms
A43: CAS EC 260 | B43: EC | C43: Development Economics | D43: Economics | E43: Elective (200+ cap) | F43: 200 | G43: 4 | H43: Economics: max four 200+ level courses transferred after matriculation | I43: Fully synthetic course (not a real BU offering) | J43: Development Economics is an intermediate course in economics. It covers economic growth, poverty measurement, human capital and institutions, and builds toward microfinance and foreign aid. Students work through data and policy exercises, with later units on agriculture and randomized evaluations. | K43: Explain the core ideas of economic growth | Apply poverty measurement to solve standard problems | Analyze problems involving human capital | Use institutions in practical exercises | Evaluate approaches to microfinance | Communicate findings about foreign aid | L43: economic growth | poverty measurement | human capital | institutions | microfinance | foreign aid | agriculture | randomized evaluations
A44: CAS EC 270 | B44: EC | C44: Environmental Economics | D44: Economics | E44: Elective (200+ cap) | F44: 200 | G44: 4 | H44: Economics: max four 200+ level courses transferred after matriculation | I44: Fully synthetic course (not a real BU offering) | J44: Environmental Economics is an intermediate course in economics. It covers externalities, public goods, pollution regulation and carbon pricing, and builds toward cost-benefit analysis and natural resources. Students work through data and policy exercises, with later units on climate policy and valuation methods. | K44: Explain the core ideas of externalities | Apply public goods to solve standard problems | Analyze problems involving pollution regulation | Use carbon pricing in practical exercises | Evaluate approaches to cost-benefit analysis | Communicate findings about natural resources | L44: externalities | public goods | pollution regulation | carbon pricing | cost-benefit analysis | natural resources | climate policy | valuation methods
A45: CAS EC 280 | B45: EC | C45: Game Theory | D45: Economics | E45: Elective (200+ cap) | F45: 200 | G45: 4 | H45: Economics: max four 200+ level courses transferred after matriculation | I45: Fully synthetic course (not a real BU offering) | J45: Game Theory is an intermediate course in economics. It covers strategic games, Nash equilibrium, mixed strategies and sequential games, and builds toward repeated games and bargaining. Students work through data and policy exercises, with later units on auctions and mechanism design. | K45: Explain the core ideas of strategic games | Apply Nash equilibrium to solve standard problems | Analyze problems involving mixed strategies | Use sequential games in practical exercises | Evaluate approaches to repeated games | Communicate findings about bargaining | L45: strategic games | Nash equilibrium | mixed strategies | sequential games | repeated games | bargaining | auctions | mechanism design
A46: CAS EC 290 | B46: EC | C46: Economic History of the United States | D46: Economics | E46: Elective (200+ cap) | F46: 200 | G46: 4 | H46: Economics: max four 200+ level courses transferred after matriculation | I46: Fully synthetic course (not a real BU offering) | J46: Economic History of the United States is an intermediate course in economics. It covers colonial economy, industrialization, labor markets and the Great Depression, and builds toward financial crises and technological change. Students work through data and policy exercises, with later units on economic growth and government policy. | K46: Explain the core ideas of colonial economy | Apply industrialization to solve standard problems | Analyze problems involving labor markets | Use the Great Depression in practical exercises | Evaluate approaches to financial crises | Communicate findings about technological change | L46: colonial economy | industrialization | labor markets | the Great Depression | financial crises | technological change | economic growth | government policy
A47: CAS EC 305 | B47: EC | C47: Health Economics | D47: Economics | E47: Elective (200+ cap) | F47: 300 | G47: 4 | H47: Economics: max four 200+ level courses transferred after matriculation | I47: Fully synthetic course (not a real BU offering) | J47: Health Economics is an advanced course in economics. It covers demand for health care, health insurance, adverse selection and hospital markets, and builds toward pharmaceutical markets and health policy. Students work through data and policy exercises, with later units on cost-effectiveness and public health. | K47: Explain the core ideas of demand for health care | Apply health insurance to solve standard problems | Analyze problems involving adverse selection | Use hospital markets in practical exercises | Evaluate approaches to pharmaceutical markets | Communicate findings about health policy | L47: demand for health care | health insurance | adverse selection | hospital markets | pharmaceutical markets | health policy | cost-effectiveness | public health
A48: CAS EC 310 | B48: EC | C48: Urban Economics | D48: Economics | E48: Elective (200+ cap) | F48: 300 | G48: 4 | H48: Economics: max four 200+ level courses transferred after matriculation | I48: Fully synthetic course (not a real BU offering) | J48: Urban Economics is an advanced course in economics. It covers city formation, land use, housing markets and transportation, and builds toward local public goods and segregation. Students work through data and policy exercises, with later units on urban policy and agglomeration. | K48: Explain the core ideas of city formation | Apply land use to solve standard problems | Analyze problems involving housing markets | Use transportation in practical exercises | Evaluate approaches to local public goods | Communicate findings about segregation | L48: city formation | land use | housing markets | transportation | local public goods | segregation | urban policy | agglomeration
...

Sheet Schools
A1: School code | B1: Name | C1: Type | D1: Calendar | E1: Accreditation | F1: Location | G1: Role | H1: Note
A2: NEU | B2: Northeastern University | C2: Private research university (Boston) | D2: Semester | E2: Regionally accredited | F2: Boston, MA | G2: Primary source school (hackathon data) | H2: Real institution. Course codes/titles/credits from its public catalog via the hackathon workbook. Student records, grades and syllabi are synthetic and were NOT issued by Northeastern.
A3: NYU | B3: New York University | C3: Private research university (New York) | D3: Semester | E3: Regionally accredited | F3: New York, NY | G3: Primary source school (hackathon data) | H3: Real institution. Course codes/titles/credits from its public catalog via the hackathon workbook. Student records, grades and syllabi are synthetic and were NOT issued by NYU.
A4: PSC | B4: Pinecrest State College (fictional) | C4: Fictional four-year public college | D4: Quarter | E4: Regionally accredited | F4: Fictional | G4: Test helper: quarter-system conversion (NU and NYU use semesters) | H4: Fictional. Used for one summer course only.
A5: SOI | B5: Summit Online Institute (fictional) | C5: Fictional online institute | D5: Semester | E5: Not regionally accredited (national accreditor only) | F5: Online | G5: Test helper: accreditation rule | H5: Fictional. Used for the non-accredited-school test only.

Sheet External Courses
A1: Ext ID | B1: School | C1: Course code | D1: Title | E1: Credits | F1: Calendar | G1: Units if transferred | H1: Program area | I1: Course type | J1: Level | K1: Source | L1: Description | M1: Learning outcomes | N1: Topics | O1: gt_counterpart | P1: gt_overlap | Q1: gt_tier
